<?xml version="1.0"?>
<robot name="{{ config.robot_name }}" xmlns:xacro="http://ros.org/wiki/xacro">

  <xacro:macro name="base_robot">
    <!-- Constants for robot dimensions -->
    <xacro:property name="length" value="{{ config.geometry.length }}"/>
    <xacro:property name="width" value="{{ config.geometry.width }}"/>
    <xacro:property name="height" value="{{ config.geometry.height }}"/>
    <xacro:property name="wheel_radius" value="{{ config.geometry.wheel_radius }}"/>
    <xacro:property name="wheel_base" value="{{ config.geometry.wheel_base }}"/>


    <!-- Base Footprint (Root Link - Projected on ground, no inertia) -->
    <link name="base_footprint"/>

    <!-- Base Link -->
    <joint name="base_joint" type="fixed">
      <parent link="base_footprint"/>
      <child link="base_link"/>
      <origin xyz="0 0 ${wheel_radius + height/2}" rpy="0 0 0"/>
    </joint>

    <link name="base_link">
      <visual>
        <geometry>
          <box size="${length} ${width} ${height}"/>
        </geometry>
        <material name="cyan">
          <color rgba="0 1.0 1.0 1.0"/>
        </material>
      </visual>
      <collision>
         <geometry>
          <box size="${length} ${width} ${height}"/>
        </geometry>
      </collision>
      <inertial>
        <mass value="15.0"/>
        <inertia ixx="0.1" ixy="0.0" ixz="0.0" iyy="0.1" iyz="0.0" izz="0.1"/>
      </inertial>
    </link>

    <!-- Wheels (Simplified Differential Drive) -->
    <!-- Left Wheel -->
    <link name="left_wheel_link">
      <visual>
        <geometry>
          <cylinder radius="${wheel_radius}" length="0.05"/>
        </geometry>
        <material name="black">
            <color rgba="0 0 0 1"/>
        </material>
      </visual>
      <collision>
        <geometry>
          <cylinder radius="${wheel_radius}" length="0.05"/>
        </geometry>
      </collision>
       <inertial>
        <mass value="2.0"/>
        <inertia ixx="0.1" ixy="0.0" ixz="0.0" iyy="0.1" iyz="0.0" izz="0.1"/>
      </inertial>
    </link>

    <joint name="left_wheel_joint" type="continuous">
      <parent link="base_link"/>
      <child link="left_wheel_link"/>
      <origin xyz="-${length/4} ${wheel_base/2} -${height/2}" rpy="-1.5708 0 0"/>
      <axis xyz="0 0 1"/>
    </joint>

    <!-- Right Wheel -->
    <link name="right_wheel_link">
      <visual>
        <geometry>
          <cylinder radius="${wheel_radius}" length="0.05"/>
        </geometry>
        <material name="black">
            <color rgba="0 0 0 1"/>
        </material>
      </visual>
      <collision>
        <geometry>
          <cylinder radius="${wheel_radius}" length="0.05"/>
        </geometry>
      </collision>
      <inertial>
        <mass value="2.0"/>
        <inertia ixx="0.1" ixy="0.0" ixz="0.0" iyy="0.1" iyz="0.0" izz="0.1"/>
      </inertial>
    </link>

    <joint name="right_wheel_joint" type="continuous">
      <parent link="base_link"/>
      <child link="right_wheel_link"/>
      <origin xyz="-${length/4} -${wheel_base/2} -${height/2}" rpy="-1.5708 0 0"/>
      <axis xyz="0 0 1"/>
    </joint>

    <!-- Caster Wheel (to prevent tipping) -->
    <link name="caster_wheel">
      <visual>
        <geometry>
          <sphere radius="${wheel_radius/2}"/>
        </geometry>
        <material name="black"/>
      </visual>
      <collision>
        <geometry>
          <sphere radius="${wheel_radius/2}"/>
        </geometry>
      </collision>
       <inertial>
        <mass value="1.0"/>
        <inertia ixx="0.1" ixy="0.0" ixz="0.0" iyy="0.1" iyz="0.0" izz="0.1"/>
      </inertial>
    </link>

    <joint name="caster_wheel_joint" type="fixed">
      <parent link="base_link"/>
      <child link="caster_wheel"/>
      <origin xyz="${length/2 - 0.05} 0 -${height/2 + wheel_radius - wheel_radius/2}" rpy="0 0 0"/>
    </joint>
    
    <!-- Gazebo Wheel Friction Settings for traction -->
    <gazebo reference="left_wheel_link">
      <mu1>1.0</mu1>
      <mu2>1.0</mu2>
      <kp>1000000.0</kp>
      <kd>100.0</kd>
      <material>Gazebo/Black</material>
    </gazebo>
    
    <gazebo reference="right_wheel_link">
      <mu1>1.0</mu1>
      <mu2>1.0</mu2>
      <kp>1000000.0</kp>
      <kd>100.0</kd>
      <material>Gazebo/Black</material>
    </gazebo>
    
    <!-- Gazebo Caster Wheel Friction Settings -->
    <gazebo reference="caster_wheel">
      <mu1>0.0</mu1>
      <mu2>0.0</mu2>
      <kp>1000000.0</kp>
      <kd>100.0</kd>
      <material>Gazebo/Black</material>
    </gazebo>
    
    <!-- Gazebo Diff Drive Plugin (Simulation Only) -->
    {% if config.simulation %}
    <gazebo>
      <plugin name="diff_drive" filename="libgazebo_ros_diff_drive.so">
        <ros>
          <namespace>/</namespace>
        </ros>
        <left_joint>left_wheel_joint</left_joint>
        <right_joint>right_wheel_joint</right_joint>
        <wheel_separation>${wheel_base}</wheel_separation>
        <wheel_diameter>${2*wheel_radius}</wheel_diameter>
        <max_wheel_torque>20</max_wheel_torque>
        <max_wheel_acceleration>1.0</max_wheel_acceleration>
        <publish_odom>true</publish_odom>
        <publish_odom_tf>true</publish_odom_tf>
        <publish_wheel_tf>true</publish_wheel_tf>
        <odometry_frame>odom</odometry_frame>
        <robot_base_frame>base_footprint</robot_base_frame>
      </plugin>
    </gazebo>
    {% endif %}

  </xacro:macro>
  <xacro:base_robot/>

  <!-- Sensors: Conditionally include based on configuration -->
  {%- if config.sensors.lidar_2d %}
  <xacro:include filename="$(find {{config.robot_name}}_description)/urdf/sensors/lidar.xacro"/>
  <xacro:lidar_sensor/>
  {%- endif %}

  {%- if config.sensors.imu %}
  <xacro:include filename="$(find {{config.robot_name}}_description)/urdf/sensors/imu.xacro"/>
  <xacro:imu_sensor/>
  {%- endif %}

  {%- if config.sensors.lidar_3d %}
  <xacro:include filename="$(find {{config.robot_name}}_description)/urdf/sensors/lidar_3d.xacro"/>
  <xacro:lidar_3d_sensor/>
  {%- endif %}

  {%- if config.sensors.depth_camera %}
  <xacro:include filename="$(find {{config.robot_name}}_description)/urdf/sensors/depth_camera.xacro"/>
  <xacro:depth_camera_sensor/>
  {%- endif %}

  {%- if config.sensors.rgb_camera %}
  <xacro:include filename="$(find {{config.robot_name}}_description)/urdf/sensors/rgb_camera.xacro"/>
  <xacro:rgb_camera_sensor/>
  {%- endif %}

</robot>
