<?xml version="1.0"?>
<robot name="{{ config.robot_name }}" xmlns:xacro="http://ros.org/wiki/xacro">

  <xacro:macro name="base_robot">
    <!-- Constants for robot dimensions -->
    <xacro:property name="length" value="{{ config.geometry.length }}"/>
    <xacro:property name="width" value="{{ config.geometry.width }}"/>
    <xacro:property name="height" value="{{ config.geometry.height }}"/>
    <xacro:property name="wheel_radius" value="{{ config.geometry.wheel_radius }}"/>
    <xacro:property name="wheel_base" value="{{ config.geometry.wheel_base }}"/>


    <!-- Base Footprint (Root Link - Projected on ground, no inertia) -->
    <link name="base_footprint"/>

    <!-- Base Link -->
    <joint name="base_joint" type="fixed">
      <parent link="base_footprint"/>
      <child link="base_link"/>
      <origin xyz="0 0 ${height/2 + 0.05}" rpy="0 0 0"/>
    </joint>

    <link name="base_link">
      <visual>
        <geometry>
          <box size="${length} ${width} ${height}"/>
        </geometry>
        <material name="cyan">
          <color rgba="0 1.0 1.0 1.0"/>
        </material>
      </visual>
      <collision>
         <geometry>
          <box size="${length} ${width} ${height}"/>
        </geometry>
      </collision>
      <inertial>
        <mass value="15.0"/>
        <inertia ixx="0.1" ixy="0.0" ixz="0.0" iyy="0.1" iyz="0.0" izz="0.1"/>
      </inertial>
    </link>

    <!-- Wheels (Simplified Differential Drive) -->
    <!-- Left Wheel -->
    <link name="left_wheel_link">
      <visual>
        <geometry>
          <cylinder radius="${wheel_radius}" length="0.05"/>
        </geometry>
        <material name="black">
            <color rgba="0 0 0 1"/>
        </material>
      </visual>
      <collision>
        <geometry>
          <cylinder radius="${wheel_radius}" length="0.05"/>
        </geometry>
      </collision>
       <inertial>
        <mass value="2.0"/>
        <inertia ixx="0.1" ixy="0.0" ixz="0.0" iyy="0.1" iyz="0.0" izz="0.1"/>
      </inertial>
    </link>

    <joint name="left_wheel_joint" type="continuous">
      <parent link="base_link"/>
      <child link="left_wheel_link"/>
      <origin xyz="0 ${wheel_base/2} -${height/2}" rpy="-1.5708 0 0"/>
      <axis xyz="0 0 1"/>
    </joint>

    <!-- Right Wheel -->
    <link name="right_wheel_link">
      <visual>
        <geometry>
          <cylinder radius="${wheel_radius}" length="0.05"/>
        </geometry>
        <material name="black">
            <color rgba="0 0 0 1"/>
        </material>
      </visual>
      <collision>
        <geometry>
          <cylinder radius="${wheel_radius}" length="0.05"/>
        </geometry>
      </collision>
      <inertial>
        <mass value="2.0"/>
        <inertia ixx="0.1" ixy="0.0" ixz="0.0" iyy="0.1" iyz="0.0" izz="0.1"/>
      </inertial>
    </link>

    <joint name="right_wheel_joint" type="continuous">
      <parent link="base_link"/>
      <child link="right_wheel_link"/>
      <origin xyz="0 -${wheel_base/2} -${height/2}" rpy="-1.5708 0 0"/>
      <axis xyz="0 0 1"/>
    </joint>

    <!-- Caster Wheel (to prevent tipping) -->
    <link name="caster_wheel">
      <visual>
        <geometry>
          <sphere radius="${wheel_radius/2}"/>
        </geometry>
        <material name="black"/>
      </visual>
      <collision>
        <geometry>
          <sphere radius="${wheel_radius/2}"/>
        </geometry>
      </collision>
       <inertial>
        <mass value="1.0"/>
        <inertia ixx="0.1" ixy="0.0" ixz="0.0" iyy="0.1" iyz="0.0" izz="0.1"/>
      </inertial>
    </link>

    <joint name="caster_wheel_joint" type="fixed">
      <parent link="base_link"/>
      <child link="caster_wheel"/>
      <origin xyz="${length/2 - 0.05} 0 -${height/2 + wheel_radius/2}" rpy="0 0 0"/>
    </joint>
    
    <!-- Gazebo Diff Drive Plugin (Simulation Only) -->
    {% if config.simulation %}
    <gazebo>
      <plugin name="diff_drive" filename="libgazebo_ros_diff_drive.so">
        <ros>
          <namespace>/</namespace>
        </ros>
        <left_joint>left_wheel_joint</left_joint>
        <right_joint>right_wheel_joint</right_joint>
        <wheel_separation>${wheel_base}</wheel_separation>
        <wheel_diameter>${2*wheel_radius}</wheel_diameter>
        <max_wheel_torque>20</max_wheel_torque>
        <max_wheel_acceleration>1.0</max_wheel_acceleration>
        <publish_odom>true</publish_odom>
        <publish_odom_tf>true</publish_odom_tf>
        <publish_wheel_tf>true</publish_wheel_tf>
        <odometry_frame>odom</odometry_frame>
        <robot_base_frame>base_link</robot_base_frame>
      </plugin>
    </gazebo>
    {% endif %}

  </xacro:macro>
</robot>
